2018-02-14 20:19:16,373 - restLib - INFO - Uploading file/s ['pytest.ini', '__init__.py']
Uploading file/s ['pytest.ini', '__init__.py']
2018-02-14 20:19:16,392 - restLib - ERROR - Got exception in sendrequest method local variable 'url_path' referenced before assignment
Traceback (most recent call last):
  File "F:\python\jeevan\pyRestAuto\rest_lib\pyRest_lib.py", line 139, in __post_request
    self.headers ['Content-Type'] = upload_data.content_type
AttributeError: 'PyRestLib' object has no attribute 'headers'

During handling of the above exception, another exception occurred:

Traceback (most recent call last):
  File "F:\python\jeevan\pyRestAuto\rest_lib\pyRest_lib.py", line 45, in send_request
    file_paths=file_path)
  File "F:\python\jeevan\pyRestAuto\rest_lib\pyRest_lib.py", line 181, in __post_request
    "{}".format(url_path, e))
UnboundLocalError: local variable 'url_path' referenced before assignment
Got exception in sendrequest method local variable 'url_path' referenced before assignment
Traceback (most recent call last):
  File "F:\python\jeevan\pyRestAuto\rest_lib\pyRest_lib.py", line 139, in __post_request
    self.headers ['Content-Type'] = upload_data.content_type
AttributeError: 'PyRestLib' object has no attribute 'headers'

During handling of the above exception, another exception occurred:

Traceback (most recent call last):
  File "F:\python\jeevan\pyRestAuto\rest_lib\pyRest_lib.py", line 45, in send_request
    file_paths=file_path)
  File "F:\python\jeevan\pyRestAuto\rest_lib\pyRest_lib.py", line 181, in __post_request
    "{}".format(url_path, e))
UnboundLocalError: local variable 'url_path' referenced before assignment
